[2022-10-17T22:52:10.768+0000] {processor.py:156} INFO - Started process (PID=645) to work on /opt/airflow/dags/forex_data_pipeline.py
[2022-10-17T22:52:10.768+0000] {processor.py:758} INFO - Processing file /opt/airflow/dags/forex_data_pipeline.py for tasks to queue
[2022-10-17T22:52:10.768+0000] {logging_mixin.py:117} INFO - [2022-10-17T22:52:10.768+0000] {dagbag.py:525} INFO - Filling up the DagBag from /opt/airflow/dags/forex_data_pipeline.py
[2022-10-17T22:52:10.770+0000] {logging_mixin.py:117} INFO - [2022-10-17T22:52:10.769+0000] {dagbag.py:330} ERROR - Failed to import: /opt/airflow/dags/forex_data_pipeline.py
Traceback (most recent call last):
  File "/home/airflow/.local/lib/python3.7/site-packages/airflow/models/dagbag.py", line 326, in parse
    loader.exec_module(new_module)
  File "<frozen importlib._bootstrap_external>", line 728, in exec_module
  File "<frozen importlib._bootstrap>", line 219, in _call_with_frames_removed
  File "/opt/airflow/dags/forex_data_pipeline.py", line 3, in <module>
    with DAG(
TypeError: __init__() missing 1 required positional argument: 'dag_id'
[2022-10-17T22:52:10.770+0000] {processor.py:770} WARNING - No viable dags retrieved from /opt/airflow/dags/forex_data_pipeline.py
[2022-10-17T22:52:10.780+0000] {processor.py:178} INFO - Processing /opt/airflow/dags/forex_data_pipeline.py took 0.013 seconds
[2022-10-17T22:52:41.567+0000] {processor.py:156} INFO - Started process (PID=709) to work on /opt/airflow/dags/forex_data_pipeline.py
[2022-10-17T22:52:41.567+0000] {processor.py:758} INFO - Processing file /opt/airflow/dags/forex_data_pipeline.py for tasks to queue
[2022-10-17T22:52:41.567+0000] {logging_mixin.py:117} INFO - [2022-10-17T22:52:41.567+0000] {dagbag.py:525} INFO - Filling up the DagBag from /opt/airflow/dags/forex_data_pipeline.py
[2022-10-17T22:52:41.568+0000] {logging_mixin.py:117} INFO - [2022-10-17T22:52:41.568+0000] {dagbag.py:330} ERROR - Failed to import: /opt/airflow/dags/forex_data_pipeline.py
Traceback (most recent call last):
  File "/home/airflow/.local/lib/python3.7/site-packages/airflow/models/dagbag.py", line 326, in parse
    loader.exec_module(new_module)
  File "<frozen importlib._bootstrap_external>", line 728, in exec_module
  File "<frozen importlib._bootstrap>", line 219, in _call_with_frames_removed
  File "/opt/airflow/dags/forex_data_pipeline.py", line 3, in <module>
    with DAG(
TypeError: __init__() missing 1 required positional argument: 'dag_id'
[2022-10-17T22:52:41.569+0000] {processor.py:770} WARNING - No viable dags retrieved from /opt/airflow/dags/forex_data_pipeline.py
[2022-10-17T22:52:41.578+0000] {processor.py:178} INFO - Processing /opt/airflow/dags/forex_data_pipeline.py took 0.013 seconds
[2022-10-17T22:53:12.300+0000] {processor.py:156} INFO - Started process (PID=773) to work on /opt/airflow/dags/forex_data_pipeline.py
[2022-10-17T22:53:12.301+0000] {processor.py:758} INFO - Processing file /opt/airflow/dags/forex_data_pipeline.py for tasks to queue
[2022-10-17T22:53:12.301+0000] {logging_mixin.py:117} INFO - [2022-10-17T22:53:12.301+0000] {dagbag.py:525} INFO - Filling up the DagBag from /opt/airflow/dags/forex_data_pipeline.py
[2022-10-17T22:53:12.303+0000] {logging_mixin.py:117} INFO - [2022-10-17T22:53:12.302+0000] {dagbag.py:330} ERROR - Failed to import: /opt/airflow/dags/forex_data_pipeline.py
Traceback (most recent call last):
  File "/home/airflow/.local/lib/python3.7/site-packages/airflow/models/dagbag.py", line 326, in parse
    loader.exec_module(new_module)
  File "<frozen importlib._bootstrap_external>", line 728, in exec_module
  File "<frozen importlib._bootstrap>", line 219, in _call_with_frames_removed
  File "/opt/airflow/dags/forex_data_pipeline.py", line 3, in <module>
    with DAG(
TypeError: __init__() missing 1 required positional argument: 'dag_id'
[2022-10-17T22:53:12.303+0000] {processor.py:770} WARNING - No viable dags retrieved from /opt/airflow/dags/forex_data_pipeline.py
[2022-10-17T22:53:12.314+0000] {processor.py:178} INFO - Processing /opt/airflow/dags/forex_data_pipeline.py took 0.016 seconds
[2022-10-17T22:53:28.265+0000] {processor.py:156} INFO - Started process (PID=819) to work on /opt/airflow/dags/forex_data_pipeline.py
[2022-10-17T22:53:28.266+0000] {processor.py:758} INFO - Processing file /opt/airflow/dags/forex_data_pipeline.py for tasks to queue
[2022-10-17T22:53:28.266+0000] {logging_mixin.py:117} INFO - [2022-10-17T22:53:28.266+0000] {dagbag.py:525} INFO - Filling up the DagBag from /opt/airflow/dags/forex_data_pipeline.py
[2022-10-17T22:53:28.269+0000] {logging_mixin.py:117} INFO - [2022-10-17T22:53:28.267+0000] {dagbag.py:330} ERROR - Failed to import: /opt/airflow/dags/forex_data_pipeline.py
Traceback (most recent call last):
  File "/home/airflow/.local/lib/python3.7/site-packages/airflow/models/dagbag.py", line 326, in parse
    loader.exec_module(new_module)
  File "<frozen importlib._bootstrap_external>", line 728, in exec_module
  File "<frozen importlib._bootstrap>", line 219, in _call_with_frames_removed
  File "/opt/airflow/dags/forex_data_pipeline.py", line 4, in <module>
    ""
  File "/home/airflow/.local/lib/python3.7/site-packages/airflow/models/dag.py", line 424, in __init__
    validate_key(dag_id)
  File "/home/airflow/.local/lib/python3.7/site-packages/airflow/utils/helpers.py", line 56, in validate_key
    f"The key {k!r} has to be made of alphanumeric characters, dashes, "
airflow.exceptions.AirflowException: The key '' has to be made of alphanumeric characters, dashes, dots and underscores exclusively
[2022-10-17T22:53:28.270+0000] {processor.py:770} WARNING - No viable dags retrieved from /opt/airflow/dags/forex_data_pipeline.py
[2022-10-17T22:53:28.282+0000] {processor.py:178} INFO - Processing /opt/airflow/dags/forex_data_pipeline.py took 0.019 seconds
[2022-10-17T22:53:58.392+0000] {processor.py:156} INFO - Started process (PID=883) to work on /opt/airflow/dags/forex_data_pipeline.py
[2022-10-17T22:53:58.393+0000] {processor.py:758} INFO - Processing file /opt/airflow/dags/forex_data_pipeline.py for tasks to queue
[2022-10-17T22:53:58.393+0000] {logging_mixin.py:117} INFO - [2022-10-17T22:53:58.393+0000] {dagbag.py:525} INFO - Filling up the DagBag from /opt/airflow/dags/forex_data_pipeline.py
[2022-10-17T22:53:58.395+0000] {logging_mixin.py:117} INFO - [2022-10-17T22:53:58.394+0000] {dagbag.py:330} ERROR - Failed to import: /opt/airflow/dags/forex_data_pipeline.py
Traceback (most recent call last):
  File "/home/airflow/.local/lib/python3.7/site-packages/airflow/models/dagbag.py", line 326, in parse
    loader.exec_module(new_module)
  File "<frozen importlib._bootstrap_external>", line 728, in exec_module
  File "<frozen importlib._bootstrap>", line 219, in _call_with_frames_removed
  File "/opt/airflow/dags/forex_data_pipeline.py", line 4, in <module>
    ""
  File "/home/airflow/.local/lib/python3.7/site-packages/airflow/models/dag.py", line 424, in __init__
    validate_key(dag_id)
  File "/home/airflow/.local/lib/python3.7/site-packages/airflow/utils/helpers.py", line 56, in validate_key
    f"The key {k!r} has to be made of alphanumeric characters, dashes, "
airflow.exceptions.AirflowException: The key '' has to be made of alphanumeric characters, dashes, dots and underscores exclusively
[2022-10-17T22:53:58.395+0000] {processor.py:770} WARNING - No viable dags retrieved from /opt/airflow/dags/forex_data_pipeline.py
[2022-10-17T22:53:58.405+0000] {processor.py:178} INFO - Processing /opt/airflow/dags/forex_data_pipeline.py took 0.014 seconds
[2022-10-17T22:54:28.514+0000] {processor.py:156} INFO - Started process (PID=961) to work on /opt/airflow/dags/forex_data_pipeline.py
[2022-10-17T22:54:28.515+0000] {processor.py:758} INFO - Processing file /opt/airflow/dags/forex_data_pipeline.py for tasks to queue
[2022-10-17T22:54:28.515+0000] {logging_mixin.py:117} INFO - [2022-10-17T22:54:28.515+0000] {dagbag.py:525} INFO - Filling up the DagBag from /opt/airflow/dags/forex_data_pipeline.py
[2022-10-17T22:54:28.517+0000] {logging_mixin.py:117} INFO - [2022-10-17T22:54:28.516+0000] {dagbag.py:330} ERROR - Failed to import: /opt/airflow/dags/forex_data_pipeline.py
Traceback (most recent call last):
  File "/home/airflow/.local/lib/python3.7/site-packages/airflow/models/dagbag.py", line 326, in parse
    loader.exec_module(new_module)
  File "<frozen importlib._bootstrap_external>", line 728, in exec_module
  File "<frozen importlib._bootstrap>", line 219, in _call_with_frames_removed
  File "/opt/airflow/dags/forex_data_pipeline.py", line 4, in <module>
    ""
  File "/home/airflow/.local/lib/python3.7/site-packages/airflow/models/dag.py", line 424, in __init__
    validate_key(dag_id)
  File "/home/airflow/.local/lib/python3.7/site-packages/airflow/utils/helpers.py", line 56, in validate_key
    f"The key {k!r} has to be made of alphanumeric characters, dashes, "
airflow.exceptions.AirflowException: The key '' has to be made of alphanumeric characters, dashes, dots and underscores exclusively
[2022-10-17T22:54:28.517+0000] {processor.py:770} WARNING - No viable dags retrieved from /opt/airflow/dags/forex_data_pipeline.py
[2022-10-17T22:54:28.527+0000] {processor.py:178} INFO - Processing /opt/airflow/dags/forex_data_pipeline.py took 0.015 seconds
[2022-10-17T22:54:58.674+0000] {processor.py:156} INFO - Started process (PID=1066) to work on /opt/airflow/dags/forex_data_pipeline.py
[2022-10-17T22:54:58.675+0000] {processor.py:758} INFO - Processing file /opt/airflow/dags/forex_data_pipeline.py for tasks to queue
[2022-10-17T22:54:58.675+0000] {logging_mixin.py:117} INFO - [2022-10-17T22:54:58.675+0000] {dagbag.py:525} INFO - Filling up the DagBag from /opt/airflow/dags/forex_data_pipeline.py
[2022-10-17T22:54:58.677+0000] {logging_mixin.py:117} INFO - [2022-10-17T22:54:58.676+0000] {dagbag.py:330} ERROR - Failed to import: /opt/airflow/dags/forex_data_pipeline.py
Traceback (most recent call last):
  File "/home/airflow/.local/lib/python3.7/site-packages/airflow/models/dagbag.py", line 326, in parse
    loader.exec_module(new_module)
  File "<frozen importlib._bootstrap_external>", line 728, in exec_module
  File "<frozen importlib._bootstrap>", line 219, in _call_with_frames_removed
  File "/opt/airflow/dags/forex_data_pipeline.py", line 4, in <module>
    ""
  File "/home/airflow/.local/lib/python3.7/site-packages/airflow/models/dag.py", line 424, in __init__
    validate_key(dag_id)
  File "/home/airflow/.local/lib/python3.7/site-packages/airflow/utils/helpers.py", line 56, in validate_key
    f"The key {k!r} has to be made of alphanumeric characters, dashes, "
airflow.exceptions.AirflowException: The key '' has to be made of alphanumeric characters, dashes, dots and underscores exclusively
[2022-10-17T22:54:58.677+0000] {processor.py:770} WARNING - No viable dags retrieved from /opt/airflow/dags/forex_data_pipeline.py
[2022-10-17T22:54:58.689+0000] {processor.py:178} INFO - Processing /opt/airflow/dags/forex_data_pipeline.py took 0.016 seconds
[2022-10-17T22:55:28.711+0000] {processor.py:156} INFO - Started process (PID=1149) to work on /opt/airflow/dags/forex_data_pipeline.py
[2022-10-17T22:55:28.711+0000] {processor.py:758} INFO - Processing file /opt/airflow/dags/forex_data_pipeline.py for tasks to queue
[2022-10-17T22:55:28.711+0000] {logging_mixin.py:117} INFO - [2022-10-17T22:55:28.711+0000] {dagbag.py:525} INFO - Filling up the DagBag from /opt/airflow/dags/forex_data_pipeline.py
[2022-10-17T22:55:28.713+0000] {logging_mixin.py:117} INFO - [2022-10-17T22:55:28.712+0000] {dagbag.py:330} ERROR - Failed to import: /opt/airflow/dags/forex_data_pipeline.py
Traceback (most recent call last):
  File "/home/airflow/.local/lib/python3.7/site-packages/airflow/models/dagbag.py", line 326, in parse
    loader.exec_module(new_module)
  File "<frozen importlib._bootstrap_external>", line 728, in exec_module
  File "<frozen importlib._bootstrap>", line 219, in _call_with_frames_removed
  File "/opt/airflow/dags/forex_data_pipeline.py", line 4, in <module>
    ""
  File "/home/airflow/.local/lib/python3.7/site-packages/airflow/models/dag.py", line 424, in __init__
    validate_key(dag_id)
  File "/home/airflow/.local/lib/python3.7/site-packages/airflow/utils/helpers.py", line 56, in validate_key
    f"The key {k!r} has to be made of alphanumeric characters, dashes, "
airflow.exceptions.AirflowException: The key '' has to be made of alphanumeric characters, dashes, dots and underscores exclusively
[2022-10-17T22:55:28.713+0000] {processor.py:770} WARNING - No viable dags retrieved from /opt/airflow/dags/forex_data_pipeline.py
[2022-10-17T22:55:28.723+0000] {processor.py:178} INFO - Processing /opt/airflow/dags/forex_data_pipeline.py took 0.014 seconds
[2022-10-17T22:55:58.803+0000] {processor.py:156} INFO - Started process (PID=1220) to work on /opt/airflow/dags/forex_data_pipeline.py
[2022-10-17T22:55:58.803+0000] {processor.py:758} INFO - Processing file /opt/airflow/dags/forex_data_pipeline.py for tasks to queue
[2022-10-17T22:55:58.804+0000] {logging_mixin.py:117} INFO - [2022-10-17T22:55:58.804+0000] {dagbag.py:525} INFO - Filling up the DagBag from /opt/airflow/dags/forex_data_pipeline.py
[2022-10-17T22:55:58.805+0000] {logging_mixin.py:117} INFO - [2022-10-17T22:55:58.804+0000] {dagbag.py:330} ERROR - Failed to import: /opt/airflow/dags/forex_data_pipeline.py
Traceback (most recent call last):
  File "/home/airflow/.local/lib/python3.7/site-packages/airflow/models/dagbag.py", line 326, in parse
    loader.exec_module(new_module)
  File "<frozen importlib._bootstrap_external>", line 728, in exec_module
  File "<frozen importlib._bootstrap>", line 219, in _call_with_frames_removed
  File "/opt/airflow/dags/forex_data_pipeline.py", line 4, in <module>
    ""
  File "/home/airflow/.local/lib/python3.7/site-packages/airflow/models/dag.py", line 424, in __init__
    validate_key(dag_id)
  File "/home/airflow/.local/lib/python3.7/site-packages/airflow/utils/helpers.py", line 56, in validate_key
    f"The key {k!r} has to be made of alphanumeric characters, dashes, "
airflow.exceptions.AirflowException: The key '' has to be made of alphanumeric characters, dashes, dots and underscores exclusively
[2022-10-17T22:55:58.806+0000] {processor.py:770} WARNING - No viable dags retrieved from /opt/airflow/dags/forex_data_pipeline.py
[2022-10-17T22:55:58.816+0000] {processor.py:178} INFO - Processing /opt/airflow/dags/forex_data_pipeline.py took 0.015 seconds
[2022-10-17T22:56:29.530+0000] {processor.py:156} INFO - Started process (PID=1361) to work on /opt/airflow/dags/forex_data_pipeline.py
[2022-10-17T22:56:29.531+0000] {processor.py:758} INFO - Processing file /opt/airflow/dags/forex_data_pipeline.py for tasks to queue
[2022-10-17T22:56:29.531+0000] {logging_mixin.py:117} INFO - [2022-10-17T22:56:29.531+0000] {dagbag.py:525} INFO - Filling up the DagBag from /opt/airflow/dags/forex_data_pipeline.py
[2022-10-17T22:56:29.533+0000] {logging_mixin.py:117} INFO - [2022-10-17T22:56:29.532+0000] {dagbag.py:330} ERROR - Failed to import: /opt/airflow/dags/forex_data_pipeline.py
Traceback (most recent call last):
  File "/home/airflow/.local/lib/python3.7/site-packages/airflow/models/dagbag.py", line 326, in parse
    loader.exec_module(new_module)
  File "<frozen importlib._bootstrap_external>", line 728, in exec_module
  File "<frozen importlib._bootstrap>", line 219, in _call_with_frames_removed
  File "/opt/airflow/dags/forex_data_pipeline.py", line 4, in <module>
    ""
  File "/home/airflow/.local/lib/python3.7/site-packages/airflow/models/dag.py", line 424, in __init__
    validate_key(dag_id)
  File "/home/airflow/.local/lib/python3.7/site-packages/airflow/utils/helpers.py", line 56, in validate_key
    f"The key {k!r} has to be made of alphanumeric characters, dashes, "
airflow.exceptions.AirflowException: The key '' has to be made of alphanumeric characters, dashes, dots and underscores exclusively
[2022-10-17T22:56:29.533+0000] {processor.py:770} WARNING - No viable dags retrieved from /opt/airflow/dags/forex_data_pipeline.py
[2022-10-17T22:56:29.543+0000] {processor.py:178} INFO - Processing /opt/airflow/dags/forex_data_pipeline.py took 0.014 seconds
[2022-10-17T22:57:00.437+0000] {processor.py:156} INFO - Started process (PID=1813) to work on /opt/airflow/dags/forex_data_pipeline.py
[2022-10-17T22:57:00.438+0000] {processor.py:758} INFO - Processing file /opt/airflow/dags/forex_data_pipeline.py for tasks to queue
[2022-10-17T22:57:00.438+0000] {logging_mixin.py:117} INFO - [2022-10-17T22:57:00.438+0000] {dagbag.py:525} INFO - Filling up the DagBag from /opt/airflow/dags/forex_data_pipeline.py
[2022-10-17T22:57:00.440+0000] {logging_mixin.py:117} INFO - [2022-10-17T22:57:00.439+0000] {dagbag.py:330} ERROR - Failed to import: /opt/airflow/dags/forex_data_pipeline.py
Traceback (most recent call last):
  File "/home/airflow/.local/lib/python3.7/site-packages/airflow/models/dagbag.py", line 326, in parse
    loader.exec_module(new_module)
  File "<frozen importlib._bootstrap_external>", line 728, in exec_module
  File "<frozen importlib._bootstrap>", line 219, in _call_with_frames_removed
  File "/opt/airflow/dags/forex_data_pipeline.py", line 4, in <module>
    ""
  File "/home/airflow/.local/lib/python3.7/site-packages/airflow/models/dag.py", line 424, in __init__
    validate_key(dag_id)
  File "/home/airflow/.local/lib/python3.7/site-packages/airflow/utils/helpers.py", line 56, in validate_key
    f"The key {k!r} has to be made of alphanumeric characters, dashes, "
airflow.exceptions.AirflowException: The key '' has to be made of alphanumeric characters, dashes, dots and underscores exclusively
[2022-10-17T22:57:00.441+0000] {processor.py:770} WARNING - No viable dags retrieved from /opt/airflow/dags/forex_data_pipeline.py
[2022-10-17T22:57:00.454+0000] {processor.py:178} INFO - Processing /opt/airflow/dags/forex_data_pipeline.py took 0.019 seconds
[2022-10-17T22:57:31.181+0000] {processor.py:156} INFO - Started process (PID=2614) to work on /opt/airflow/dags/forex_data_pipeline.py
[2022-10-17T22:57:31.181+0000] {processor.py:758} INFO - Processing file /opt/airflow/dags/forex_data_pipeline.py for tasks to queue
[2022-10-17T22:57:31.182+0000] {logging_mixin.py:117} INFO - [2022-10-17T22:57:31.182+0000] {dagbag.py:525} INFO - Filling up the DagBag from /opt/airflow/dags/forex_data_pipeline.py
[2022-10-17T22:57:31.183+0000] {logging_mixin.py:117} INFO - [2022-10-17T22:57:31.182+0000] {dagbag.py:330} ERROR - Failed to import: /opt/airflow/dags/forex_data_pipeline.py
Traceback (most recent call last):
  File "/home/airflow/.local/lib/python3.7/site-packages/airflow/models/dagbag.py", line 326, in parse
    loader.exec_module(new_module)
  File "<frozen importlib._bootstrap_external>", line 728, in exec_module
  File "<frozen importlib._bootstrap>", line 219, in _call_with_frames_removed
  File "/opt/airflow/dags/forex_data_pipeline.py", line 4, in <module>
    ""
  File "/home/airflow/.local/lib/python3.7/site-packages/airflow/models/dag.py", line 424, in __init__
    validate_key(dag_id)
  File "/home/airflow/.local/lib/python3.7/site-packages/airflow/utils/helpers.py", line 56, in validate_key
    f"The key {k!r} has to be made of alphanumeric characters, dashes, "
airflow.exceptions.AirflowException: The key '' has to be made of alphanumeric characters, dashes, dots and underscores exclusively
[2022-10-17T22:57:31.183+0000] {processor.py:770} WARNING - No viable dags retrieved from /opt/airflow/dags/forex_data_pipeline.py
[2022-10-17T22:57:31.196+0000] {processor.py:178} INFO - Processing /opt/airflow/dags/forex_data_pipeline.py took 0.017 seconds
[2022-10-17T22:58:01.984+0000] {processor.py:156} INFO - Started process (PID=3164) to work on /opt/airflow/dags/forex_data_pipeline.py
[2022-10-17T22:58:01.985+0000] {processor.py:758} INFO - Processing file /opt/airflow/dags/forex_data_pipeline.py for tasks to queue
[2022-10-17T22:58:01.985+0000] {logging_mixin.py:117} INFO - [2022-10-17T22:58:01.985+0000] {dagbag.py:525} INFO - Filling up the DagBag from /opt/airflow/dags/forex_data_pipeline.py
[2022-10-17T22:58:01.986+0000] {logging_mixin.py:117} INFO - [2022-10-17T22:58:01.986+0000] {dagbag.py:330} ERROR - Failed to import: /opt/airflow/dags/forex_data_pipeline.py
Traceback (most recent call last):
  File "/home/airflow/.local/lib/python3.7/site-packages/airflow/models/dagbag.py", line 326, in parse
    loader.exec_module(new_module)
  File "<frozen importlib._bootstrap_external>", line 728, in exec_module
  File "<frozen importlib._bootstrap>", line 219, in _call_with_frames_removed
  File "/opt/airflow/dags/forex_data_pipeline.py", line 4, in <module>
    ""
  File "/home/airflow/.local/lib/python3.7/site-packages/airflow/models/dag.py", line 424, in __init__
    validate_key(dag_id)
  File "/home/airflow/.local/lib/python3.7/site-packages/airflow/utils/helpers.py", line 56, in validate_key
    f"The key {k!r} has to be made of alphanumeric characters, dashes, "
airflow.exceptions.AirflowException: The key '' has to be made of alphanumeric characters, dashes, dots and underscores exclusively
[2022-10-17T22:58:01.987+0000] {processor.py:770} WARNING - No viable dags retrieved from /opt/airflow/dags/forex_data_pipeline.py
[2022-10-17T22:58:01.997+0000] {processor.py:178} INFO - Processing /opt/airflow/dags/forex_data_pipeline.py took 0.015 seconds
[2022-10-17T22:58:32.808+0000] {processor.py:156} INFO - Started process (PID=3510) to work on /opt/airflow/dags/forex_data_pipeline.py
[2022-10-17T22:58:32.808+0000] {processor.py:758} INFO - Processing file /opt/airflow/dags/forex_data_pipeline.py for tasks to queue
[2022-10-17T22:58:32.808+0000] {logging_mixin.py:117} INFO - [2022-10-17T22:58:32.808+0000] {dagbag.py:525} INFO - Filling up the DagBag from /opt/airflow/dags/forex_data_pipeline.py
[2022-10-17T22:58:32.810+0000] {logging_mixin.py:117} INFO - [2022-10-17T22:58:32.809+0000] {dagbag.py:330} ERROR - Failed to import: /opt/airflow/dags/forex_data_pipeline.py
Traceback (most recent call last):
  File "/home/airflow/.local/lib/python3.7/site-packages/airflow/models/dagbag.py", line 326, in parse
    loader.exec_module(new_module)
  File "<frozen importlib._bootstrap_external>", line 728, in exec_module
  File "<frozen importlib._bootstrap>", line 219, in _call_with_frames_removed
  File "/opt/airflow/dags/forex_data_pipeline.py", line 4, in <module>
    ""
  File "/home/airflow/.local/lib/python3.7/site-packages/airflow/models/dag.py", line 424, in __init__
    validate_key(dag_id)
  File "/home/airflow/.local/lib/python3.7/site-packages/airflow/utils/helpers.py", line 56, in validate_key
    f"The key {k!r} has to be made of alphanumeric characters, dashes, "
airflow.exceptions.AirflowException: The key '' has to be made of alphanumeric characters, dashes, dots and underscores exclusively
[2022-10-17T22:58:32.810+0000] {processor.py:770} WARNING - No viable dags retrieved from /opt/airflow/dags/forex_data_pipeline.py
[2022-10-17T22:58:32.822+0000] {processor.py:178} INFO - Processing /opt/airflow/dags/forex_data_pipeline.py took 0.016 seconds
[2022-10-17T22:59:03.603+0000] {processor.py:156} INFO - Started process (PID=3788) to work on /opt/airflow/dags/forex_data_pipeline.py
[2022-10-17T22:59:03.603+0000] {processor.py:758} INFO - Processing file /opt/airflow/dags/forex_data_pipeline.py for tasks to queue
[2022-10-17T22:59:03.604+0000] {logging_mixin.py:117} INFO - [2022-10-17T22:59:03.604+0000] {dagbag.py:525} INFO - Filling up the DagBag from /opt/airflow/dags/forex_data_pipeline.py
[2022-10-17T22:59:03.605+0000] {logging_mixin.py:117} INFO - [2022-10-17T22:59:03.604+0000] {dagbag.py:330} ERROR - Failed to import: /opt/airflow/dags/forex_data_pipeline.py
Traceback (most recent call last):
  File "/home/airflow/.local/lib/python3.7/site-packages/airflow/models/dagbag.py", line 326, in parse
    loader.exec_module(new_module)
  File "<frozen importlib._bootstrap_external>", line 728, in exec_module
  File "<frozen importlib._bootstrap>", line 219, in _call_with_frames_removed
  File "/opt/airflow/dags/forex_data_pipeline.py", line 4, in <module>
    ""
  File "/home/airflow/.local/lib/python3.7/site-packages/airflow/models/dag.py", line 424, in __init__
    validate_key(dag_id)
  File "/home/airflow/.local/lib/python3.7/site-packages/airflow/utils/helpers.py", line 56, in validate_key
    f"The key {k!r} has to be made of alphanumeric characters, dashes, "
airflow.exceptions.AirflowException: The key '' has to be made of alphanumeric characters, dashes, dots and underscores exclusively
[2022-10-17T22:59:03.606+0000] {processor.py:770} WARNING - No viable dags retrieved from /opt/airflow/dags/forex_data_pipeline.py
[2022-10-17T22:59:03.616+0000] {processor.py:178} INFO - Processing /opt/airflow/dags/forex_data_pipeline.py took 0.015 seconds
[2022-10-17T22:59:25.802+0000] {processor.py:156} INFO - Started process (PID=3878) to work on /opt/airflow/dags/forex_data_pipeline.py
[2022-10-17T22:59:25.802+0000] {processor.py:758} INFO - Processing file /opt/airflow/dags/forex_data_pipeline.py for tasks to queue
[2022-10-17T22:59:25.803+0000] {logging_mixin.py:117} INFO - [2022-10-17T22:59:25.803+0000] {dagbag.py:525} INFO - Filling up the DagBag from /opt/airflow/dags/forex_data_pipeline.py
[2022-10-17T22:59:25.804+0000] {logging_mixin.py:117} INFO - [2022-10-17T22:59:25.804+0000] {dagbag.py:330} ERROR - Failed to import: /opt/airflow/dags/forex_data_pipeline.py
Traceback (most recent call last):
  File "/home/airflow/.local/lib/python3.7/site-packages/airflow/models/dagbag.py", line 326, in parse
    loader.exec_module(new_module)
  File "<frozen importlib._bootstrap_external>", line 728, in exec_module
  File "<frozen importlib._bootstrap>", line 219, in _call_with_frames_removed
  File "/opt/airflow/dags/forex_data_pipeline.py", line 6, in <module>
    start_date=datetime(2021, 1, 1)
TypeError: __init__() got an unexpected keyword argument 'id'
[2022-10-17T22:59:25.804+0000] {processor.py:770} WARNING - No viable dags retrieved from /opt/airflow/dags/forex_data_pipeline.py
[2022-10-17T22:59:25.815+0000] {processor.py:178} INFO - Processing /opt/airflow/dags/forex_data_pipeline.py took 0.015 seconds
[2022-10-17T22:59:37.428+0000] {processor.py:156} INFO - Started process (PID=3921) to work on /opt/airflow/dags/forex_data_pipeline.py
[2022-10-17T22:59:37.428+0000] {processor.py:758} INFO - Processing file /opt/airflow/dags/forex_data_pipeline.py for tasks to queue
[2022-10-17T22:59:37.429+0000] {logging_mixin.py:117} INFO - [2022-10-17T22:59:37.428+0000] {dagbag.py:525} INFO - Filling up the DagBag from /opt/airflow/dags/forex_data_pipeline.py
[2022-10-17T22:59:37.430+0000] {logging_mixin.py:117} INFO - [2022-10-17T22:59:37.429+0000] {dagbag.py:330} ERROR - Failed to import: /opt/airflow/dags/forex_data_pipeline.py
Traceback (most recent call last):
  File "/home/airflow/.local/lib/python3.7/site-packages/airflow/models/dagbag.py", line 326, in parse
    loader.exec_module(new_module)
  File "<frozen importlib._bootstrap_external>", line 728, in exec_module
  File "<frozen importlib._bootstrap>", line 219, in _call_with_frames_removed
  File "/opt/airflow/dags/forex_data_pipeline.py", line 6, in <module>
    start_date=datetime(2021, 1, 1)
TypeError: __init__() got an unexpected keyword argument 'id'
[2022-10-17T22:59:37.430+0000] {processor.py:770} WARNING - No viable dags retrieved from /opt/airflow/dags/forex_data_pipeline.py
[2022-10-17T22:59:37.441+0000] {processor.py:178} INFO - Processing /opt/airflow/dags/forex_data_pipeline.py took 0.015 seconds
[2022-10-17T22:59:52.513+0000] {processor.py:156} INFO - Started process (PID=3940) to work on /opt/airflow/dags/forex_data_pipeline.py
[2022-10-17T22:59:52.513+0000] {processor.py:758} INFO - Processing file /opt/airflow/dags/forex_data_pipeline.py for tasks to queue
[2022-10-17T22:59:52.513+0000] {logging_mixin.py:117} INFO - [2022-10-17T22:59:52.513+0000] {dagbag.py:525} INFO - Filling up the DagBag from /opt/airflow/dags/forex_data_pipeline.py
[2022-10-17T22:59:52.515+0000] {logging_mixin.py:117} INFO - [2022-10-17T22:59:52.514+0000] {dagbag.py:330} ERROR - Failed to import: /opt/airflow/dags/forex_data_pipeline.py
Traceback (most recent call last):
  File "/home/airflow/.local/lib/python3.7/site-packages/airflow/models/dagbag.py", line 326, in parse
    loader.exec_module(new_module)
  File "<frozen importlib._bootstrap_external>", line 728, in exec_module
  File "<frozen importlib._bootstrap>", line 219, in _call_with_frames_removed
  File "/opt/airflow/dags/forex_data_pipeline.py", line 6, in <module>
    start_date=datetime(2021, 1, 1),
TypeError: __init__() got an unexpected keyword argument 'id'
[2022-10-17T22:59:52.515+0000] {processor.py:770} WARNING - No viable dags retrieved from /opt/airflow/dags/forex_data_pipeline.py
[2022-10-17T22:59:52.526+0000] {processor.py:178} INFO - Processing /opt/airflow/dags/forex_data_pipeline.py took 0.015 seconds
[2022-10-17T22:59:59.735+0000] {processor.py:156} INFO - Started process (PID=3967) to work on /opt/airflow/dags/forex_data_pipeline.py
[2022-10-17T22:59:59.735+0000] {processor.py:758} INFO - Processing file /opt/airflow/dags/forex_data_pipeline.py for tasks to queue
[2022-10-17T22:59:59.736+0000] {logging_mixin.py:117} INFO - [2022-10-17T22:59:59.736+0000] {dagbag.py:525} INFO - Filling up the DagBag from /opt/airflow/dags/forex_data_pipeline.py
[2022-10-17T22:59:59.737+0000] {logging_mixin.py:117} INFO - [2022-10-17T22:59:59.737+0000] {dagbag.py:330} ERROR - Failed to import: /opt/airflow/dags/forex_data_pipeline.py
Traceback (most recent call last):
  File "/home/airflow/.local/lib/python3.7/site-packages/airflow/models/dagbag.py", line 326, in parse
    loader.exec_module(new_module)
  File "<frozen importlib._bootstrap_external>", line 728, in exec_module
  File "<frozen importlib._bootstrap>", line 219, in _call_with_frames_removed
  File "/opt/airflow/dags/forex_data_pipeline.py", line 6, in <module>
    start_date=datetime(2021, 1, 1),
TypeError: __init__() got an unexpected keyword argument 'id'
[2022-10-17T22:59:59.737+0000] {processor.py:770} WARNING - No viable dags retrieved from /opt/airflow/dags/forex_data_pipeline.py
[2022-10-17T22:59:59.748+0000] {processor.py:178} INFO - Processing /opt/airflow/dags/forex_data_pipeline.py took 0.015 seconds
[2022-10-17T23:00:15.259+0000] {processor.py:156} INFO - Started process (PID=3996) to work on /opt/airflow/dags/forex_data_pipeline.py
[2022-10-17T23:00:15.259+0000] {processor.py:758} INFO - Processing file /opt/airflow/dags/forex_data_pipeline.py for tasks to queue
[2022-10-17T23:00:15.260+0000] {logging_mixin.py:117} INFO - [2022-10-17T23:00:15.260+0000] {dagbag.py:525} INFO - Filling up the DagBag from /opt/airflow/dags/forex_data_pipeline.py
[2022-10-17T23:00:15.261+0000] {logging_mixin.py:117} INFO - [2022-10-17T23:00:15.261+0000] {dagbag.py:330} ERROR - Failed to import: /opt/airflow/dags/forex_data_pipeline.py
Traceback (most recent call last):
  File "/home/airflow/.local/lib/python3.7/site-packages/airflow/models/dagbag.py", line 326, in parse
    loader.exec_module(new_module)
  File "<frozen importlib._bootstrap_external>", line 728, in exec_module
  File "<frozen importlib._bootstrap>", line 219, in _call_with_frames_removed
  File "/opt/airflow/dags/forex_data_pipeline.py", line 7, in <module>
    schedule_interval=datetime(),
TypeError: function missing required argument 'year' (pos 1)
[2022-10-17T23:00:15.262+0000] {processor.py:770} WARNING - No viable dags retrieved from /opt/airflow/dags/forex_data_pipeline.py
[2022-10-17T23:00:15.272+0000] {processor.py:178} INFO - Processing /opt/airflow/dags/forex_data_pipeline.py took 0.015 seconds
[2022-10-17T23:00:21.286+0000] {processor.py:156} INFO - Started process (PID=3997) to work on /opt/airflow/dags/forex_data_pipeline.py
[2022-10-17T23:00:21.286+0000] {processor.py:758} INFO - Processing file /opt/airflow/dags/forex_data_pipeline.py for tasks to queue
[2022-10-17T23:00:21.287+0000] {logging_mixin.py:117} INFO - [2022-10-17T23:00:21.287+0000] {dagbag.py:525} INFO - Filling up the DagBag from /opt/airflow/dags/forex_data_pipeline.py
[2022-10-17T23:00:21.288+0000] {logging_mixin.py:117} INFO - [2022-10-17T23:00:21.288+0000] {dagbag.py:330} ERROR - Failed to import: /opt/airflow/dags/forex_data_pipeline.py
Traceback (most recent call last):
  File "/home/airflow/.local/lib/python3.7/site-packages/airflow/models/dagbag.py", line 326, in parse
    loader.exec_module(new_module)
  File "<frozen importlib._bootstrap_external>", line 728, in exec_module
  File "<frozen importlib._bootstrap>", line 219, in _call_with_frames_removed
  File "/opt/airflow/dags/forex_data_pipeline.py", line 7, in <module>
    schedule_interval="@daily",
TypeError: __init__() got an unexpected keyword argument 'id'
[2022-10-17T23:00:21.288+0000] {processor.py:770} WARNING - No viable dags retrieved from /opt/airflow/dags/forex_data_pipeline.py
[2022-10-17T23:00:21.300+0000] {processor.py:178} INFO - Processing /opt/airflow/dags/forex_data_pipeline.py took 0.016 seconds
[2022-10-17T23:00:51.999+0000] {processor.py:156} INFO - Started process (PID=4061) to work on /opt/airflow/dags/forex_data_pipeline.py
[2022-10-17T23:00:51.999+0000] {processor.py:758} INFO - Processing file /opt/airflow/dags/forex_data_pipeline.py for tasks to queue
[2022-10-17T23:00:51.999+0000] {logging_mixin.py:117} INFO - [2022-10-17T23:00:51.999+0000] {dagbag.py:525} INFO - Filling up the DagBag from /opt/airflow/dags/forex_data_pipeline.py
[2022-10-17T23:00:52.001+0000] {logging_mixin.py:117} INFO - [2022-10-17T23:00:52.000+0000] {dagbag.py:330} ERROR - Failed to import: /opt/airflow/dags/forex_data_pipeline.py
Traceback (most recent call last):
  File "/home/airflow/.local/lib/python3.7/site-packages/airflow/models/dagbag.py", line 326, in parse
    loader.exec_module(new_module)
  File "<frozen importlib._bootstrap_external>", line 728, in exec_module
  File "<frozen importlib._bootstrap>", line 219, in _call_with_frames_removed
  File "/opt/airflow/dags/forex_data_pipeline.py", line 7, in <module>
    schedule_interval="@daily",
TypeError: __init__() got an unexpected keyword argument 'id'
[2022-10-17T23:00:52.001+0000] {processor.py:770} WARNING - No viable dags retrieved from /opt/airflow/dags/forex_data_pipeline.py
[2022-10-17T23:00:52.012+0000] {processor.py:178} INFO - Processing /opt/airflow/dags/forex_data_pipeline.py took 0.015 seconds
[2022-10-17T23:01:22.722+0000] {processor.py:156} INFO - Started process (PID=4124) to work on /opt/airflow/dags/forex_data_pipeline.py
[2022-10-17T23:01:22.723+0000] {processor.py:758} INFO - Processing file /opt/airflow/dags/forex_data_pipeline.py for tasks to queue
[2022-10-17T23:01:22.723+0000] {logging_mixin.py:117} INFO - [2022-10-17T23:01:22.723+0000] {dagbag.py:525} INFO - Filling up the DagBag from /opt/airflow/dags/forex_data_pipeline.py
[2022-10-17T23:01:22.724+0000] {logging_mixin.py:117} INFO - [2022-10-17T23:01:22.724+0000] {dagbag.py:330} ERROR - Failed to import: /opt/airflow/dags/forex_data_pipeline.py
Traceback (most recent call last):
  File "/home/airflow/.local/lib/python3.7/site-packages/airflow/models/dagbag.py", line 326, in parse
    loader.exec_module(new_module)
  File "<frozen importlib._bootstrap_external>", line 728, in exec_module
  File "<frozen importlib._bootstrap>", line 219, in _call_with_frames_removed
  File "/opt/airflow/dags/forex_data_pipeline.py", line 7, in <module>
    schedule_interval="@daily",
TypeError: __init__() got an unexpected keyword argument 'id'
[2022-10-17T23:01:22.724+0000] {processor.py:770} WARNING - No viable dags retrieved from /opt/airflow/dags/forex_data_pipeline.py
[2022-10-17T23:01:22.734+0000] {processor.py:178} INFO - Processing /opt/airflow/dags/forex_data_pipeline.py took 0.014 seconds
[2022-10-17T23:01:31.034+0000] {processor.py:156} INFO - Started process (PID=4141) to work on /opt/airflow/dags/forex_data_pipeline.py
[2022-10-17T23:01:31.035+0000] {processor.py:758} INFO - Processing file /opt/airflow/dags/forex_data_pipeline.py for tasks to queue
[2022-10-17T23:01:31.035+0000] {logging_mixin.py:117} INFO - [2022-10-17T23:01:31.035+0000] {dagbag.py:525} INFO - Filling up the DagBag from /opt/airflow/dags/forex_data_pipeline.py
[2022-10-17T23:01:31.037+0000] {logging_mixin.py:117} INFO - [2022-10-17T23:01:31.036+0000] {dagbag.py:330} ERROR - Failed to import: /opt/airflow/dags/forex_data_pipeline.py
Traceback (most recent call last):
  File "/home/airflow/.local/lib/python3.7/site-packages/airflow/models/dagbag.py", line 326, in parse
    loader.exec_module(new_module)
  File "<frozen importlib._bootstrap_external>", line 728, in exec_module
  File "<frozen importlib._bootstrap>", line 219, in _call_with_frames_removed
  File "/opt/airflow/dags/forex_data_pipeline.py", line 12, in <module>
    schedule_interval="@daily",
TypeError: __init__() got an unexpected keyword argument 'id'
[2022-10-17T23:01:31.037+0000] {processor.py:770} WARNING - No viable dags retrieved from /opt/airflow/dags/forex_data_pipeline.py
[2022-10-17T23:01:31.049+0000] {processor.py:178} INFO - Processing /opt/airflow/dags/forex_data_pipeline.py took 0.017 seconds
[2022-10-17T23:01:57.686+0000] {processor.py:156} INFO - Started process (PID=4189) to work on /opt/airflow/dags/forex_data_pipeline.py
[2022-10-17T23:01:57.687+0000] {processor.py:758} INFO - Processing file /opt/airflow/dags/forex_data_pipeline.py for tasks to queue
[2022-10-17T23:01:57.687+0000] {logging_mixin.py:117} INFO - [2022-10-17T23:01:57.687+0000] {dagbag.py:525} INFO - Filling up the DagBag from /opt/airflow/dags/forex_data_pipeline.py
[2022-10-17T23:01:57.688+0000] {logging_mixin.py:117} INFO - [2022-10-17T23:01:57.688+0000] {dagbag.py:330} ERROR - Failed to import: /opt/airflow/dags/forex_data_pipeline.py
Traceback (most recent call last):
  File "/home/airflow/.local/lib/python3.7/site-packages/airflow/models/dagbag.py", line 326, in parse
    loader.exec_module(new_module)
  File "<frozen importlib._bootstrap_external>", line 728, in exec_module
  File "<frozen importlib._bootstrap>", line 219, in _call_with_frames_removed
  File "/opt/airflow/dags/forex_data_pipeline.py", line 14, in <module>
    schedule_interval="@daily",
TypeError: __init__() got an unexpected keyword argument 'id'
[2022-10-17T23:01:57.689+0000] {processor.py:770} WARNING - No viable dags retrieved from /opt/airflow/dags/forex_data_pipeline.py
[2022-10-17T23:01:57.698+0000] {processor.py:178} INFO - Processing /opt/airflow/dags/forex_data_pipeline.py took 0.014 seconds
[2022-10-17T23:02:00.814+0000] {processor.py:156} INFO - Started process (PID=4193) to work on /opt/airflow/dags/forex_data_pipeline.py
[2022-10-17T23:02:00.814+0000] {processor.py:758} INFO - Processing file /opt/airflow/dags/forex_data_pipeline.py for tasks to queue
[2022-10-17T23:02:00.815+0000] {logging_mixin.py:117} INFO - [2022-10-17T23:02:00.814+0000] {dagbag.py:525} INFO - Filling up the DagBag from /opt/airflow/dags/forex_data_pipeline.py
[2022-10-17T23:02:00.816+0000] {logging_mixin.py:117} INFO - [2022-10-17T23:02:00.816+0000] {dagbag.py:330} ERROR - Failed to import: /opt/airflow/dags/forex_data_pipeline.py
Traceback (most recent call last):
  File "/home/airflow/.local/lib/python3.7/site-packages/airflow/models/dagbag.py", line 326, in parse
    loader.exec_module(new_module)
  File "<frozen importlib._bootstrap_external>", line 728, in exec_module
  File "<frozen importlib._bootstrap>", line 219, in _call_with_frames_removed
  File "/opt/airflow/dags/forex_data_pipeline.py", line 14, in <module>
    schedule_interval="@daily",
TypeError: __init__() got an unexpected keyword argument 'id'
[2022-10-17T23:02:00.816+0000] {processor.py:770} WARNING - No viable dags retrieved from /opt/airflow/dags/forex_data_pipeline.py
[2022-10-17T23:02:00.828+0000] {processor.py:178} INFO - Processing /opt/airflow/dags/forex_data_pipeline.py took 0.016 seconds
[2022-10-17T23:02:09.365+0000] {processor.py:156} INFO - Started process (PID=4236) to work on /opt/airflow/dags/forex_data_pipeline.py
[2022-10-17T23:02:09.365+0000] {processor.py:758} INFO - Processing file /opt/airflow/dags/forex_data_pipeline.py for tasks to queue
[2022-10-17T23:02:09.366+0000] {logging_mixin.py:117} INFO - [2022-10-17T23:02:09.365+0000] {dagbag.py:525} INFO - Filling up the DagBag from /opt/airflow/dags/forex_data_pipeline.py
[2022-10-17T23:02:09.367+0000] {logging_mixin.py:117} INFO - [2022-10-17T23:02:09.366+0000] {dagbag.py:330} ERROR - Failed to import: /opt/airflow/dags/forex_data_pipeline.py
Traceback (most recent call last):
  File "/home/airflow/.local/lib/python3.7/site-packages/airflow/models/dagbag.py", line 326, in parse
    loader.exec_module(new_module)
  File "<frozen importlib._bootstrap_external>", line 728, in exec_module
  File "<frozen importlib._bootstrap>", line 219, in _call_with_frames_removed
  File "/opt/airflow/dags/forex_data_pipeline.py", line 15, in <module>
    schedule_interval="@daily",
TypeError: __init__() got an unexpected keyword argument 'id'
[2022-10-17T23:02:09.367+0000] {processor.py:770} WARNING - No viable dags retrieved from /opt/airflow/dags/forex_data_pipeline.py
[2022-10-17T23:02:09.377+0000] {processor.py:178} INFO - Processing /opt/airflow/dags/forex_data_pipeline.py took 0.015 seconds
[2022-10-17T23:02:31.563+0000] {processor.py:156} INFO - Started process (PID=4258) to work on /opt/airflow/dags/forex_data_pipeline.py
[2022-10-17T23:02:31.564+0000] {processor.py:758} INFO - Processing file /opt/airflow/dags/forex_data_pipeline.py for tasks to queue
[2022-10-17T23:02:31.564+0000] {logging_mixin.py:117} INFO - [2022-10-17T23:02:31.564+0000] {dagbag.py:525} INFO - Filling up the DagBag from /opt/airflow/dags/forex_data_pipeline.py
[2022-10-17T23:02:31.565+0000] {logging_mixin.py:117} INFO - [2022-10-17T23:02:31.565+0000] {dagbag.py:330} ERROR - Failed to import: /opt/airflow/dags/forex_data_pipeline.py
Traceback (most recent call last):
  File "/home/airflow/.local/lib/python3.7/site-packages/airflow/models/dagbag.py", line 326, in parse
    loader.exec_module(new_module)
  File "<frozen importlib._bootstrap_external>", line 724, in exec_module
  File "<frozen importlib._bootstrap_external>", line 860, in get_code
  File "<frozen importlib._bootstrap_external>", line 791, in source_to_code
  File "<frozen importlib._bootstrap>", line 219, in _call_with_frames_removed
  File "/opt/airflow/dags/forex_data_pipeline.py", line 16
    default_args
    ^
SyntaxError: positional argument follows keyword argument
[2022-10-17T23:02:31.566+0000] {processor.py:770} WARNING - No viable dags retrieved from /opt/airflow/dags/forex_data_pipeline.py
[2022-10-17T23:02:31.577+0000] {processor.py:178} INFO - Processing /opt/airflow/dags/forex_data_pipeline.py took 0.016 seconds
[2022-10-17T23:02:32.743+0000] {processor.py:156} INFO - Started process (PID=4263) to work on /opt/airflow/dags/forex_data_pipeline.py
[2022-10-17T23:02:32.743+0000] {processor.py:758} INFO - Processing file /opt/airflow/dags/forex_data_pipeline.py for tasks to queue
[2022-10-17T23:02:32.744+0000] {logging_mixin.py:117} INFO - [2022-10-17T23:02:32.744+0000] {dagbag.py:525} INFO - Filling up the DagBag from /opt/airflow/dags/forex_data_pipeline.py
[2022-10-17T23:02:32.745+0000] {logging_mixin.py:117} INFO - [2022-10-17T23:02:32.744+0000] {dagbag.py:330} ERROR - Failed to import: /opt/airflow/dags/forex_data_pipeline.py
Traceback (most recent call last):
  File "/home/airflow/.local/lib/python3.7/site-packages/airflow/models/dagbag.py", line 326, in parse
    loader.exec_module(new_module)
  File "<frozen importlib._bootstrap_external>", line 724, in exec_module
  File "<frozen importlib._bootstrap_external>", line 860, in get_code
  File "<frozen importlib._bootstrap_external>", line 791, in source_to_code
  File "<frozen importlib._bootstrap>", line 219, in _call_with_frames_removed
  File "/opt/airflow/dags/forex_data_pipeline.py", line 16
    default_args,
    ^
SyntaxError: positional argument follows keyword argument
[2022-10-17T23:02:32.745+0000] {processor.py:770} WARNING - No viable dags retrieved from /opt/airflow/dags/forex_data_pipeline.py
[2022-10-17T23:02:32.757+0000] {processor.py:178} INFO - Processing /opt/airflow/dags/forex_data_pipeline.py took 0.016 seconds
[2022-10-17T23:02:50.225+0000] {processor.py:156} INFO - Started process (PID=4311) to work on /opt/airflow/dags/forex_data_pipeline.py
[2022-10-17T23:02:50.226+0000] {processor.py:758} INFO - Processing file /opt/airflow/dags/forex_data_pipeline.py for tasks to queue
[2022-10-17T23:02:50.226+0000] {logging_mixin.py:117} INFO - [2022-10-17T23:02:50.226+0000] {dagbag.py:525} INFO - Filling up the DagBag from /opt/airflow/dags/forex_data_pipeline.py
[2022-10-17T23:02:50.227+0000] {logging_mixin.py:117} INFO - [2022-10-17T23:02:50.227+0000] {dagbag.py:330} ERROR - Failed to import: /opt/airflow/dags/forex_data_pipeline.py
Traceback (most recent call last):
  File "/home/airflow/.local/lib/python3.7/site-packages/airflow/models/dagbag.py", line 326, in parse
    loader.exec_module(new_module)
  File "<frozen importlib._bootstrap_external>", line 724, in exec_module
  File "<frozen importlib._bootstrap_external>", line 860, in get_code
  File "<frozen importlib._bootstrap_external>", line 791, in source_to_code
  File "<frozen importlib._bootstrap>", line 219, in _call_with_frames_removed
  File "/opt/airflow/dags/forex_data_pipeline.py", line 17
    default_args,
    ^
SyntaxError: positional argument follows keyword argument
[2022-10-17T23:02:50.227+0000] {processor.py:770} WARNING - No viable dags retrieved from /opt/airflow/dags/forex_data_pipeline.py
[2022-10-17T23:02:50.239+0000] {processor.py:178} INFO - Processing /opt/airflow/dags/forex_data_pipeline.py took 0.016 seconds
[2022-10-17T23:02:51.255+0000] {processor.py:156} INFO - Started process (PID=4312) to work on /opt/airflow/dags/forex_data_pipeline.py
[2022-10-17T23:02:51.255+0000] {processor.py:758} INFO - Processing file /opt/airflow/dags/forex_data_pipeline.py for tasks to queue
[2022-10-17T23:02:51.256+0000] {logging_mixin.py:117} INFO - [2022-10-17T23:02:51.255+0000] {dagbag.py:525} INFO - Filling up the DagBag from /opt/airflow/dags/forex_data_pipeline.py
[2022-10-17T23:02:51.257+0000] {logging_mixin.py:117} INFO - [2022-10-17T23:02:51.256+0000] {dagbag.py:330} ERROR - Failed to import: /opt/airflow/dags/forex_data_pipeline.py
Traceback (most recent call last):
  File "/home/airflow/.local/lib/python3.7/site-packages/airflow/models/dagbag.py", line 326, in parse
    loader.exec_module(new_module)
  File "<frozen importlib._bootstrap_external>", line 724, in exec_module
  File "<frozen importlib._bootstrap_external>", line 860, in get_code
  File "<frozen importlib._bootstrap_external>", line 791, in source_to_code
  File "<frozen importlib._bootstrap>", line 219, in _call_with_frames_removed
  File "/opt/airflow/dags/forex_data_pipeline.py", line 17
    default_args,
    ^
SyntaxError: positional argument follows keyword argument
[2022-10-17T23:02:51.257+0000] {processor.py:770} WARNING - No viable dags retrieved from /opt/airflow/dags/forex_data_pipeline.py
[2022-10-17T23:02:51.267+0000] {processor.py:178} INFO - Processing /opt/airflow/dags/forex_data_pipeline.py took 0.013 seconds
[2022-10-17T23:03:22.014+0000] {processor.py:156} INFO - Started process (PID=4376) to work on /opt/airflow/dags/forex_data_pipeline.py
[2022-10-17T23:03:22.014+0000] {processor.py:758} INFO - Processing file /opt/airflow/dags/forex_data_pipeline.py for tasks to queue
[2022-10-17T23:03:22.015+0000] {logging_mixin.py:117} INFO - [2022-10-17T23:03:22.015+0000] {dagbag.py:525} INFO - Filling up the DagBag from /opt/airflow/dags/forex_data_pipeline.py
[2022-10-17T23:03:22.016+0000] {logging_mixin.py:117} INFO - [2022-10-17T23:03:22.016+0000] {dagbag.py:330} ERROR - Failed to import: /opt/airflow/dags/forex_data_pipeline.py
Traceback (most recent call last):
  File "/home/airflow/.local/lib/python3.7/site-packages/airflow/models/dagbag.py", line 326, in parse
    loader.exec_module(new_module)
  File "<frozen importlib._bootstrap_external>", line 724, in exec_module
  File "<frozen importlib._bootstrap_external>", line 860, in get_code
  File "<frozen importlib._bootstrap_external>", line 791, in source_to_code
  File "<frozen importlib._bootstrap>", line 219, in _call_with_frames_removed
  File "/opt/airflow/dags/forex_data_pipeline.py", line 17
    default_args,
    ^
SyntaxError: positional argument follows keyword argument
[2022-10-17T23:03:22.016+0000] {processor.py:770} WARNING - No viable dags retrieved from /opt/airflow/dags/forex_data_pipeline.py
[2022-10-17T23:03:22.027+0000] {processor.py:178} INFO - Processing /opt/airflow/dags/forex_data_pipeline.py took 0.016 seconds
[2022-10-17T23:03:26.038+0000] {processor.py:156} INFO - Started process (PID=4377) to work on /opt/airflow/dags/forex_data_pipeline.py
[2022-10-17T23:03:26.038+0000] {processor.py:758} INFO - Processing file /opt/airflow/dags/forex_data_pipeline.py for tasks to queue
[2022-10-17T23:03:26.039+0000] {logging_mixin.py:117} INFO - [2022-10-17T23:03:26.038+0000] {dagbag.py:525} INFO - Filling up the DagBag from /opt/airflow/dags/forex_data_pipeline.py
[2022-10-17T23:03:26.040+0000] {logging_mixin.py:117} INFO - [2022-10-17T23:03:26.040+0000] {dagbag.py:330} ERROR - Failed to import: /opt/airflow/dags/forex_data_pipeline.py
Traceback (most recent call last):
  File "/home/airflow/.local/lib/python3.7/site-packages/airflow/models/dagbag.py", line 326, in parse
    loader.exec_module(new_module)
  File "<frozen importlib._bootstrap_external>", line 728, in exec_module
  File "<frozen importlib._bootstrap>", line 219, in _call_with_frames_removed
  File "/opt/airflow/dags/forex_data_pipeline.py", line 17, in <module>
    default_args=default_args,
TypeError: __init__() got an unexpected keyword argument 'id'
[2022-10-17T23:03:26.040+0000] {processor.py:770} WARNING - No viable dags retrieved from /opt/airflow/dags/forex_data_pipeline.py
[2022-10-17T23:03:26.052+0000] {processor.py:178} INFO - Processing /opt/airflow/dags/forex_data_pipeline.py took 0.015 seconds
[2022-10-17T23:03:56.852+0000] {processor.py:156} INFO - Started process (PID=4441) to work on /opt/airflow/dags/forex_data_pipeline.py
[2022-10-17T23:03:56.853+0000] {processor.py:758} INFO - Processing file /opt/airflow/dags/forex_data_pipeline.py for tasks to queue
[2022-10-17T23:03:56.853+0000] {logging_mixin.py:117} INFO - [2022-10-17T23:03:56.853+0000] {dagbag.py:525} INFO - Filling up the DagBag from /opt/airflow/dags/forex_data_pipeline.py
[2022-10-17T23:03:56.854+0000] {logging_mixin.py:117} INFO - [2022-10-17T23:03:56.854+0000] {dagbag.py:330} ERROR - Failed to import: /opt/airflow/dags/forex_data_pipeline.py
Traceback (most recent call last):
  File "/home/airflow/.local/lib/python3.7/site-packages/airflow/models/dagbag.py", line 326, in parse
    loader.exec_module(new_module)
  File "<frozen importlib._bootstrap_external>", line 728, in exec_module
  File "<frozen importlib._bootstrap>", line 219, in _call_with_frames_removed
  File "/opt/airflow/dags/forex_data_pipeline.py", line 17, in <module>
    default_args=default_args,
TypeError: __init__() got an unexpected keyword argument 'id'
[2022-10-17T23:03:56.855+0000] {processor.py:770} WARNING - No viable dags retrieved from /opt/airflow/dags/forex_data_pipeline.py
[2022-10-17T23:03:56.866+0000] {processor.py:178} INFO - Processing /opt/airflow/dags/forex_data_pipeline.py took 0.016 seconds
[2022-10-17T23:04:19.622+0000] {processor.py:156} INFO - Started process (PID=4496) to work on /opt/airflow/dags/forex_data_pipeline.py
[2022-10-17T23:04:19.622+0000] {processor.py:758} INFO - Processing file /opt/airflow/dags/forex_data_pipeline.py for tasks to queue
[2022-10-17T23:04:19.623+0000] {logging_mixin.py:117} INFO - [2022-10-17T23:04:19.623+0000] {dagbag.py:525} INFO - Filling up the DagBag from /opt/airflow/dags/forex_data_pipeline.py
[2022-10-17T23:04:19.632+0000] {processor.py:768} INFO - DAG(s) dict_keys(['forex_data_pipeline']) retrieved from /opt/airflow/dags/forex_data_pipeline.py
[2022-10-17T23:04:19.770+0000] {logging_mixin.py:117} INFO - [2022-10-17T23:04:19.770+0000] {manager.py:507} INFO - Created Permission View: can edit on DAG:forex_data_pipeline
[2022-10-17T23:04:19.775+0000] {logging_mixin.py:117} INFO - [2022-10-17T23:04:19.775+0000] {manager.py:507} INFO - Created Permission View: can delete on DAG:forex_data_pipeline
[2022-10-17T23:04:19.779+0000] {logging_mixin.py:117} INFO - [2022-10-17T23:04:19.779+0000] {manager.py:507} INFO - Created Permission View: can read on DAG:forex_data_pipeline
[2022-10-17T23:04:19.779+0000] {logging_mixin.py:117} INFO - [2022-10-17T23:04:19.779+0000] {dag.py:2573} INFO - Sync 1 DAGs
[2022-10-17T23:04:19.787+0000] {logging_mixin.py:117} INFO - [2022-10-17T23:04:19.787+0000] {dag.py:2594} INFO - Creating ORM DAG for forex_data_pipeline
[2022-10-17T23:04:19.795+0000] {logging_mixin.py:117} INFO - [2022-10-17T23:04:19.795+0000] {dag.py:3328} INFO - Setting next_dagrun for forex_data_pipeline to 2021-01-01T00:00:00+00:00, run_after=2021-01-02T00:00:00+00:00
[2022-10-17T23:04:19.806+0000] {processor.py:178} INFO - Processing /opt/airflow/dags/forex_data_pipeline.py took 0.185 seconds
[2022-10-17T23:04:50.426+0000] {processor.py:156} INFO - Started process (PID=4560) to work on /opt/airflow/dags/forex_data_pipeline.py
[2022-10-17T23:04:50.427+0000] {processor.py:758} INFO - Processing file /opt/airflow/dags/forex_data_pipeline.py for tasks to queue
[2022-10-17T23:04:50.427+0000] {logging_mixin.py:117} INFO - [2022-10-17T23:04:50.427+0000] {dagbag.py:525} INFO - Filling up the DagBag from /opt/airflow/dags/forex_data_pipeline.py
[2022-10-17T23:04:50.436+0000] {processor.py:768} INFO - DAG(s) dict_keys(['forex_data_pipeline']) retrieved from /opt/airflow/dags/forex_data_pipeline.py
[2022-10-17T23:04:50.459+0000] {logging_mixin.py:117} INFO - [2022-10-17T23:04:50.459+0000] {dag.py:2573} INFO - Sync 1 DAGs
[2022-10-17T23:04:50.476+0000] {logging_mixin.py:117} INFO - [2022-10-17T23:04:50.476+0000] {dag.py:3328} INFO - Setting next_dagrun for forex_data_pipeline to 2021-01-01T00:00:00+00:00, run_after=2021-01-02T00:00:00+00:00
[2022-10-17T23:04:50.488+0000] {processor.py:178} INFO - Processing /opt/airflow/dags/forex_data_pipeline.py took 0.063 seconds
[2022-10-17T23:05:06.782+0000] {processor.py:156} INFO - Started process (PID=4577) to work on /opt/airflow/dags/forex_data_pipeline.py
[2022-10-17T23:05:06.783+0000] {processor.py:758} INFO - Processing file /opt/airflow/dags/forex_data_pipeline.py for tasks to queue
[2022-10-17T23:05:06.783+0000] {logging_mixin.py:117} INFO - [2022-10-17T23:05:06.783+0000] {dagbag.py:525} INFO - Filling up the DagBag from /opt/airflow/dags/forex_data_pipeline.py
[2022-10-17T23:05:06.792+0000] {processor.py:768} INFO - DAG(s) dict_keys(['forex_data_pipeline']) retrieved from /opt/airflow/dags/forex_data_pipeline.py
[2022-10-17T23:05:06.839+0000] {logging_mixin.py:117} INFO - [2022-10-17T23:05:06.838+0000] {dag.py:2573} INFO - Sync 1 DAGs
[2022-10-17T23:05:06.856+0000] {logging_mixin.py:117} INFO - [2022-10-17T23:05:06.856+0000] {dag.py:3328} INFO - Setting next_dagrun for forex_data_pipeline to 2022-10-16T00:00:00+00:00, run_after=2022-10-17T00:00:00+00:00
[2022-10-17T23:05:06.868+0000] {processor.py:178} INFO - Processing /opt/airflow/dags/forex_data_pipeline.py took 0.088 seconds
[2022-10-17T23:05:36.892+0000] {processor.py:156} INFO - Started process (PID=4641) to work on /opt/airflow/dags/forex_data_pipeline.py
[2022-10-17T23:05:36.893+0000] {processor.py:758} INFO - Processing file /opt/airflow/dags/forex_data_pipeline.py for tasks to queue
[2022-10-17T23:05:36.893+0000] {logging_mixin.py:117} INFO - [2022-10-17T23:05:36.893+0000] {dagbag.py:525} INFO - Filling up the DagBag from /opt/airflow/dags/forex_data_pipeline.py
[2022-10-17T23:05:36.901+0000] {processor.py:768} INFO - DAG(s) dict_keys(['forex_data_pipeline']) retrieved from /opt/airflow/dags/forex_data_pipeline.py
[2022-10-17T23:05:36.923+0000] {logging_mixin.py:117} INFO - [2022-10-17T23:05:36.923+0000] {dag.py:2573} INFO - Sync 1 DAGs
[2022-10-17T23:05:36.942+0000] {logging_mixin.py:117} INFO - [2022-10-17T23:05:36.942+0000] {dag.py:3328} INFO - Setting next_dagrun for forex_data_pipeline to 2022-10-16T00:00:00+00:00, run_after=2022-10-17T00:00:00+00:00
[2022-10-17T23:05:36.953+0000] {processor.py:178} INFO - Processing /opt/airflow/dags/forex_data_pipeline.py took 0.063 seconds
